<?xml version="1.0"?>
<robot xmlns:xacro="http://www.ros.org/wiki/xacro">
  <!-- Variables -->
  <xacro:property name="wheel_radius" value="0.035" />
  <xacro:property name="wheel_width" value="0.04" />
  <xacro:property name="wheel_gap" value="0.009" />


  <!-- Wheel Macro -->
  <xacro:macro name="wheel" params="prefix parent x y z z_sign rx ry rz p
                                    mesh_file_wheel">

    <joint name="${prefix}_joint" type="continuous">
      <parent link="${parent}"></parent>
      <child link="${prefix}_wheel"></child>
      <origin xyz="${base_length/2 - 0.23} ${p*0.217} -0.032" rpy="0 0 0" />
      <axis xyz="0 1 0" />
  </joint>

    <link name="${prefix}_wheel">
      <visual>
        <origin xyz="${x} ${y} ${z}" rpy="${rx} ${ry} ${rz}"/>
       
        <geometry>
          <mesh filename="file://${mesh_file_wheel}" />
        </geometry>
        <material name="black"/>
      </visual>
      <collision>
        <origin xyz="0 0 0" rpy="${pi/2} 0 0"/>
        <geometry>
          <cylinder radius="${wheel_radius}" length="${wheel_width}"/>
        </geometry>
      </collision>
      <xacro:inertial_cylinder mass="0.1" radius="${wheel_radius}" length="${wheel_width}">
        <origin xyz="0 0 0" rpy="0 0 0"/>
      </xacro:inertial_cylinder>
    </link>

    <!-- Gazebo reference -->
    <gazebo reference="${prefix}_wheel">
        <material>Gazebo/Black</material>
        <mu1>0.9</mu1>   <!-- friction parameters for the wheels -->
        <mu2>0.9</mu2>
        <kp>1000000.0</kp>
        <kd>1.0</kd>
    </gazebo>

  </xacro:macro>
</robot>